<dec f='include/python3.5m/pyerrors.h' l='113' type='int PyErr_ExceptionMatches(PyObject * )'/>
<use f='tensorflow/tensorflow/python/lib/core/py_func.cc' l='190' u='c' c='_ZN10tensorflow12_GLOBAL__N_112DoCallPyFuncEPNS0_6PyCallEPb'/>
<use f='tensorflow/tensorflow/python/lib/core/py_func.cc' l='191' u='c' c='_ZN10tensorflow12_GLOBAL__N_112DoCallPyFuncEPNS0_6PyCallEPb'/>
<use f='tensorflow/tensorflow/python/lib/core/py_func.cc' l='193' u='c' c='_ZN10tensorflow12_GLOBAL__N_112DoCallPyFuncEPNS0_6PyCallEPb'/>
<use f='tensorflow/tensorflow/python/lib/core/py_func.cc' l='196' u='c' c='_ZN10tensorflow12_GLOBAL__N_112DoCallPyFuncEPNS0_6PyCallEPb'/>
<use f='tensorflow/tensorflow/python/lib/core/py_func.cc' l='198' u='c' c='_ZN10tensorflow12_GLOBAL__N_112DoCallPyFuncEPNS0_6PyCallEPb'/>
