<dec f='include/python3.5m/pyerrors.h' l='78' type='void PyErr_SetObject(PyObject * , PyObject * )'/>
<use f='tensorflow/tensorflow/python/eager/pywrap_tfe_src.cc' l='677' u='c' c='_Z22RaiseFallbackExceptionPKc'/>
<use f='tensorflow/tensorflow/python/eager/pywrap_tfe_src.cc' l='695' u='c' c='_Z31MaybeRaiseExceptionFromTFStatusP9TF_StatusP7_object'/>
<use f='tensorflow/tensorflow/python/eager/pywrap_tfe_src.cc' l='714' u='c' c='_Z29MaybeRaiseExceptionFromStatusRKN10tensorflow6StatusEP7_object'/>
